[zjq@openeuler-riscv-4-4 envoy-1.26.4]$ bazel build -c opt --workspace_status_command= --verbose_failures envoy
INFO: Repository com_github_luajit_luajit instantiated at:
  /home/zjq/build_factory/envoy/envoy-1.26.4/WORKSPACE:13:19: in <toplevel>
  /home/zjq/build_factory/envoy/envoy-1.26.4/bazel/repositories.bzl:275:30: in envoy_dependencies
  /home/zjq/build_factory/envoy/envoy-1.26.4/bazel/repositories.bzl:1177:26: in _com_github_luajit_luajit
  /home/zjq/build_factory/envoy/envoy-1.26.4/bazel/repositories.bzl:30:23: in external_http_archive
  /home/zjq/.cache/bazel/_bazel_zjq/ce2d960f2051ba39ca8054ce19936793/external/envoy_api/bazel/envoy_http_archive.bzl:16:17: in envoy_http_archive
Repository rule http_archive defined at:
  /home/zjq/.cache/bazel/_bazel_zjq/ce2d960f2051ba39ca8054ce19936793/external/bazel_tools/tools/build_defs/repo/http.bzl:372:31: in <toplevel>
INFO: repository @com_github_luajit_luajit' used the following cache hits instead of downloading the corresponding file.
 * Hash '57ad1e3737c18a0ba7f447239449caa9cf4901e8881479475445252148b8fe34' for https://github.com/Boring545/LuaJIT/archive/2.1.0.tar.gz
If the definition of 'repository @com_github_luajit_luajit' was updated, verify that the hashes were also updated.
ERROR: An error occurred during the fetch of repository 'com_github_luajit_luajit':
   Traceback (most recent call last):
        File "/home/zjq/.cache/bazel/_bazel_zjq/ce2d960f2051ba39ca8054ce19936793/external/bazel_tools/tools/build_defs/repo/http.bzl", line 143, column 10, in _http_archive_impl
                patch(ctx, auth = auth)
        File "/home/zjq/.cache/bazel/_bazel_zjq/ce2d960f2051ba39ca8054ce19936793/external/bazel_tools/tools/build_defs/repo/utils.bzl", line 193, column 21, in patch
                fail("Error applying patch command %s:\n%s%s" %
Error in fail: Error applying patch command chmod u+x build.py:
chmod: cannot access 'build.py': No such file or directory
ERROR: /home/zjq/build_factory/envoy/envoy-1.26.4/WORKSPACE:13:19: fetching http_archive rule //external:com_github_luajit_luajit: Traceback (most recent call last):
        File "/home/zjq/.cache/bazel/_bazel_zjq/ce2d960f2051ba39ca8054ce19936793/external/bazel_tools/tools/build_defs/repo/http.bzl", line 143, column 10, in _http_archive_impl
                patch(ctx, auth = auth)
        File "/home/zjq/.cache/bazel/_bazel_zjq/ce2d960f2051ba39ca8054ce19936793/external/bazel_tools/tools/build_defs/repo/utils.bzl", line 193, column 21, in patch
                fail("Error applying patch command %s:\n%s%s" %
Error in fail: Error applying patch command chmod u+x build.py:
chmod: cannot access 'build.py': No such file or directory
ERROR: /home/zjq/.cache/bazel/_bazel_zjq/ce2d960f2051ba39ca8054ce19936793/external/envoy/bazel/foreign_cc/BUILD:79:15: @envoy//bazel/foreign_cc:luajit depends on @com_github_luajit_luajit//:all in repository @com_github_luajit_luajit which failed to fetch. no such package '@com_github_luajit_luajit//': Error applying patch command chmod u+x build.py:
chmod: cannot access 'build.py': No such file or directory
ERROR: Analysis of target '//:envoy' failed; build aborted:
INFO: Elapsed time: 2.296s
INFO: 0 processes.
FAILED: Build did NOT complete successfully (0 packages loaded, 0 targets configured)
